<?xml version="1.0" encoding="UTF-8"?>
<!-- Generated by org.testng.reporters.JUnitReportReporter -->
<testsuite hostname="JeevaLaptop" failures="1" tests="6" name="swaglab_test.LoginTest" time="18.884" errors="1" timestamp="2025-06-07T11:56:09 CDT" skipped="0">
  <testcase classname="swaglab_test.LoginTest" name="LockedUserLoginFailureTestFromExcel" time="3.045"/>
  <testcase classname="swaglab_test.LoginTest" name="CloseExcel" time="2.675">
    <error message="Cannot write data, document seems to have been closed already" type="java.io.IOException">
      <![CDATA[java.io.IOException: Cannot write data, document seems to have been closed already
at org.apache.poi.ooxml.POIXMLDocument.write(POIXMLDocument.java:230)
at swaglab_test.BaseClass.CloseExcel(BaseClass.java:53)
at java.base/jdk.internal.reflect.DirectMethodHandleAccessor.invoke(DirectMethodHandleAccessor.java:103)
at java.base/java.lang.reflect.Method.invoke(Method.java:580)
at org.testng.internal.invokers.MethodInvocationHelper.invokeMethod(MethodInvocationHelper.java:141)
at org.testng.internal.invokers.MethodInvocationHelper.invokeMethodConsideringTimeout(MethodInvocationHelper.java:71)
at org.testng.internal.invokers.ConfigInvoker.invokeConfigurationMethod(ConfigInvoker.java:400)
at org.testng.internal.invokers.ConfigInvoker.invokeConfigurations(ConfigInvoker.java:333)
at org.testng.TestRunner.invokeTestConfigurations(TestRunner.java:657)
at org.testng.TestRunner.afterRun(TestRunner.java:845)
at org.testng.TestRunner.run(TestRunner.java:618)
at org.testng.SuiteRunner.runTest(SuiteRunner.java:421)
at org.testng.SuiteRunner.runSequentially(SuiteRunner.java:413)
at org.testng.SuiteRunner.privateRun(SuiteRunner.java:373)
at org.testng.SuiteRunner.run(SuiteRunner.java:312)
at org.testng.SuiteRunnerWorker.runSuite(SuiteRunnerWorker.java:52)
at org.testng.SuiteRunnerWorker.run(SuiteRunnerWorker.java:95)
at org.testng.TestNG.runSuitesSequentially(TestNG.java:1274)
at org.testng.TestNG.runSuitesLocally(TestNG.java:1208)
at org.testng.TestNG.runSuites(TestNG.java:1112)
at org.testng.TestNG.run(TestNG.java:1079)
at org.testng.remote.AbstractRemoteTestNG.run(AbstractRemoteTestNG.java:115)
at org.testng.remote.RemoteTestNG.initAndRun(RemoteTestNG.java:293)
at org.testng.remote.RemoteTestNG.main(RemoteTestNG.java:91)
]]>
    </error>
  </testcase> <!-- CloseExcel -->
  <testcase classname="swaglab_test.LoginTest" name="LockedUserLoginFailureTestFromProperties" time="2.997"/>
  <testcase classname="swaglab_test.LoginTest" name="LoginSuccessTest" time="2.438">
    <failure message="expected [Produt] but found [Products]" type="java.lang.AssertionError">
      <![CDATA[java.lang.AssertionError: expected [Produt] but found [Products]
at org.testng.Assert.fail(Assert.java:111)
at org.testng.Assert.failNotEquals(Assert.java:1590)
at org.testng.Assert.assertEqualsImpl(Assert.java:150)
at org.testng.Assert.assertEquals(Assert.java:132)
at org.testng.Assert.assertEquals(Assert.java:656)
at org.testng.Assert.assertEquals(Assert.java:666)
at swaglab_test.LoginTest.LoginSuccessTest(LoginTest.java:35)
at java.base/jdk.internal.reflect.DirectMethodHandleAccessor.invoke(DirectMethodHandleAccessor.java:103)
at java.base/java.lang.reflect.Method.invoke(Method.java:580)
at org.testng.internal.invokers.MethodInvocationHelper.invokeMethod(MethodInvocationHelper.java:141)
at org.testng.internal.invokers.TestInvoker.invokeMethod(TestInvoker.java:687)
at org.testng.internal.invokers.TestInvoker.invokeTestMethod(TestInvoker.java:230)
at org.testng.internal.invokers.MethodRunner.runInSequence(MethodRunner.java:63)
at org.testng.internal.invokers.TestInvoker$MethodInvocationAgent.invoke(TestInvoker.java:995)
at org.testng.internal.invokers.TestInvoker.invokeTestMethods(TestInvoker.java:203)
at org.testng.internal.invokers.TestMethodWorker.invokeTestMethods(TestMethodWorker.java:154)
at org.testng.internal.invokers.TestMethodWorker.run(TestMethodWorker.java:134)
at java.base/java.util.ArrayList.forEach(ArrayList.java:1597)
at org.testng.TestRunner.privateRun(TestRunner.java:741)
at org.testng.TestRunner.run(TestRunner.java:616)
at org.testng.SuiteRunner.runTest(SuiteRunner.java:421)
at org.testng.SuiteRunner.runSequentially(SuiteRunner.java:413)
at org.testng.SuiteRunner.privateRun(SuiteRunner.java:373)
at org.testng.SuiteRunner.run(SuiteRunner.java:312)
at org.testng.SuiteRunnerWorker.runSuite(SuiteRunnerWorker.java:52)
at org.testng.SuiteRunnerWorker.run(SuiteRunnerWorker.java:95)
at org.testng.TestNG.runSuitesSequentially(TestNG.java:1274)
at org.testng.TestNG.runSuitesLocally(TestNG.java:1208)
at org.testng.TestNG.runSuites(TestNG.java:1112)
at org.testng.TestNG.run(TestNG.java:1079)
at org.testng.remote.AbstractRemoteTestNG.run(AbstractRemoteTestNG.java:115)
at org.testng.remote.RemoteTestNG.initAndRun(RemoteTestNG.java:293)
at org.testng.remote.RemoteTestNG.main(RemoteTestNG.java:91)
]]>
    </failure>
  </testcase> <!-- LoginSuccessTest -->
  <testcase classname="swaglab_test.LoginTest" name="LoginFailureTest" time="7.159"/>
  <testcase classname="swaglab_test.LoginTest" name="LockedUserLoginFailureTest" time="0.570"/>
</testsuite> <!-- swaglab_test.LoginTest -->
