<?xml version="1.0" encoding="UTF-8"?>
<!-- Generated by org.testng.reporters.JUnitReportReporter -->
<testsuite hostname="JeevaLaptop" failures="0" tests="6" name="swaglab_test.LoginTest" time="16.022" errors="1" timestamp="08 Jun 2025 14:52:49 GMT" skipped="0">
  <testcase classname="swaglab_test.LoginTest" name="CloseExcel" time="2.208">
    <error message="Cannot write data, document seems to have been closed already" type="java.io.IOException">
      <![CDATA[java.io.IOException: Cannot write data, document seems to have been closed already
at org.apache.poi.ooxml.POIXMLDocument.write(POIXMLDocument.java:230)
at swaglab_test.BaseClass.CloseExcel(BaseClass.java:67)
at java.base/jdk.internal.reflect.NativeMethodAccessorImpl.invoke0(Native Method)
at java.base/jdk.internal.reflect.NativeMethodAccessorImpl.invoke(NativeMethodAccessorImpl.java:77)
at java.base/jdk.internal.reflect.DelegatingMethodAccessorImpl.invoke(DelegatingMethodAccessorImpl.java:43)
at java.base/java.lang.reflect.Method.invoke(Method.java:568)
at org.testng.internal.MethodInvocationHelper.invokeMethod(MethodInvocationHelper.java:124)
at org.testng.internal.MethodInvocationHelper.invokeMethodConsideringTimeout(MethodInvocationHelper.java:59)
at org.testng.internal.Invoker.invokeConfigurationMethod(Invoker.java:458)
at org.testng.internal.Invoker.invokeConfigurations(Invoker.java:222)
at org.testng.internal.Invoker.invokeConfigurations(Invoker.java:142)
at org.testng.TestRunner.afterRun(TestRunner.java:725)
at org.testng.TestRunner.run(TestRunner.java:509)
at org.testng.SuiteRunner.runTest(SuiteRunner.java:455)
at org.testng.SuiteRunner.runSequentially(SuiteRunner.java:450)
at org.testng.SuiteRunner.privateRun(SuiteRunner.java:415)
at org.testng.SuiteRunner.run(SuiteRunner.java:364)
at org.testng.SuiteRunnerWorker.runSuite(SuiteRunnerWorker.java:52)
at org.testng.SuiteRunnerWorker.run(SuiteRunnerWorker.java:84)
at org.testng.TestNG.runSuitesSequentially(TestNG.java:1208)
at org.testng.TestNG.runSuitesLocally(TestNG.java:1137)
at org.testng.TestNG.runSuites(TestNG.java:1049)
at org.testng.TestNG.run(TestNG.java:1017)
at org.apache.maven.surefire.testng.TestNGExecutor.run(TestNGExecutor.java:284)
at org.apache.maven.surefire.testng.TestNGXmlTestSuite.execute(TestNGXmlTestSuite.java:75)
at org.apache.maven.surefire.testng.TestNGProvider.invoke(TestNGProvider.java:119)
at org.apache.maven.surefire.booter.ForkedBooter.runSuitesInProcess(ForkedBooter.java:428)
at org.apache.maven.surefire.booter.ForkedBooter.execute(ForkedBooter.java:162)
at org.apache.maven.surefire.booter.ForkedBooter.run(ForkedBooter.java:562)
at org.apache.maven.surefire.booter.ForkedBooter.main(ForkedBooter.java:548)
]]>
    </error>
  </testcase> <!-- CloseExcel -->
  <testcase classname="swaglab_test.LoginTest" name="LockedUserLoginFailureTestFromProperties" time="2.614"/>
  <testcase classname="swaglab_test.LoginTest" name="LoginSuccessTest" time="5.592"/>
  <testcase classname="swaglab_test.LoginTest" name="LockedUserLoginFailureTestFromExcel" time="2.641"/>
  <testcase classname="swaglab_test.LoginTest" name="LoginFailureTest" time="2.584"/>
  <testcase classname="swaglab_test.LoginTest" name="LockedUserLoginFailureTest" time="0.383"/>
</testsuite> <!-- swaglab_test.LoginTest -->
